Exception occurred in kafkaconsumer. Worker exiting.
Traceback (most recent call last):
  File "/usr/local/lib/python2.7/dist-packages/petrel-1.0.1.0.3-py2.7.egg/petrel/run.py", line 100, in main
    getattr(module, 'run')()
  File "/home/apache-storm-1.0.1/data/supervisor/stormdist/good-1-1473798976/resources/kafkaconsumer.py", line 53, in run
    KafkaConsumerSpout().run()
  File "/usr/local/lib/python2.7/dist-packages/petrel-1.0.1.0.3-py2.7.egg/petrel/storm.py", line 421, in run
    self.nextTuple()
  File "/home/apache-storm-1.0.1/data/supervisor/stormdist/good-1-1473798976/resources/kafkaconsumer.py", line 37, in nextTuple
    for message in self.consumer:
  File "/usr/local/lib/python2.7/dist-packages/kafka/vendor/six.py", line 559, in next
    return type(self).__next__(self)
  File "/usr/local/lib/python2.7/dist-packages/kafka/consumer/group.py", line 915, in __next__
    return next(self._iterator)
  File "/usr/local/lib/python2.7/dist-packages/kafka/consumer/group.py", line 855, in _message_generator
    self._client.poll(timeout_ms=poll_ms, sleep=True)
  File "/usr/local/lib/python2.7/dist-packages/kafka/client_async.py", line 509, in poll
    responses.extend(self._poll(timeout, sleep=sleep))
  File "/usr/local/lib/python2.7/dist-packages/kafka/client_async.py", line 526, in _poll
    ready = self._selector.select(timeout)
  File "/usr/local/lib/python2.7/dist-packages/kafka/vendor/selectors34.py", line 464, in select
    fd_event_list = self._epoll.poll(timeout, max_ev)
KeyboardInterrupt
